Workbook

Sheet Dashboard
A1: EMPLOYEE MARKETING VISIT DASHBOARD
A4: ="Period: " & TEXT(MIN(RawDataTable[Date]),"dd-mmm-yyyy") & " to " & TEXT(MAX(RawDataTable[Date]),"dd-mmm-yyyy") & " | Employee Focus: " & PivotData!$B$56 -> Period: 01-Jun-2026 to 30-Jun-2026 | Employee Focus: Arun
A5: Select Employee ▼ | B5: Arun
A6: =PivotData!B41 -> 300 | F6: =PivotData!B42 -> 300 | K6: =PivotData!B43 -> 0 | P6: =PivotData!B45 -> 5 | U6: =PivotData!B46 -> 30
A9: Total Visits | F9: Successful Visits | K9: Pending Visits | P9: Total Employees | U9: Total Working Days
A11: =PivotData!B47 -> 344.4 | F11: =PivotData!B48 -> 68.88 | K11: =PivotData!B49 -> 10 | P11: =PivotData!B50 -> 60 | U11: =PivotData!B51 -> 5
A14: Total Time Spent (Hrs) | F14: Avg Time / Visit (min) | K14: Avg Visits / Day | P14: Avg Visits / Employee | U14: Unique Outlets Visited
A17: PERFORMANCE & TREND CHARTS
A80: EMPLOYEE PERFORMANCE TABLE
A81: Employee | B81: Total Visits | C81: Working Days | D81: Avg Visits/Day | E81: Total Time (Hrs) | F81: Avg Time/Visit | G81: Success Rate | H81: Rank
A82: =PivotData!A3 -> Arun | B82: =PivotData!B3 -> 60 | C82: =PivotData!C3 -> 28 | D82: =PivotData!D3 -> 2.1428571 | E82: =PivotData!F3 -> 72.883333 | F82: =PivotData!G3 -> 72.883333 | G82: =PivotData!H3 -> 1 | H82: =PivotData!I3 -> 3
A83: =PivotData!A4 -> Kiran | B83: =PivotData!B4 -> 66 | C83: =PivotData!C4 -> 28 | D83: =PivotData!D4 -> 2.3571429 | E83: =PivotData!F4 -> 79.466667 | F83: =PivotData!G4 -> 72.242424 | G83: =PivotData!H4 -> 1 | H83: =PivotData!I4 -> 1
A84: =PivotData!A5 -> Priya | B84: =PivotData!B5 -> 59 | C84: =PivotData!C5 -> 29 | D84: =PivotData!D5 -> 2.0344828 | E84: =PivotData!F5 -> 58.15 | F84: =PivotData!G5 -> 59.135593 | G84: =PivotData!H5 -> 1 | H84: =PivotData!I5 -> 4
A85: =PivotData!A6 -> John | B85: =PivotData!B6 -> 61 | C85: =PivotData!C6 -> 28 | D85: =PivotData!D6 -> 2.1785714 | E85: =PivotData!F6 -> 73.05 | F85: =PivotData!G6 -> 71.852459 | G85: =PivotData!H6 -> 1 | H85: =PivotData!I6 -> 2
A86: =PivotData!A7 -> David | B86: =PivotData!B7 -> 54 | C86: =PivotData!C7 -> 26 | D86: =PivotData!D7 -> 2.0769231 | E86: =PivotData!F7 -> 60.85 | F86: =PivotData!G7 -> 67.611111 | G86: =PivotData!H7 -> 1 | H86: =PivotData!I7 -> 5
A88: OUTLET ANALYSIS TABLE
A89: Outlet Name | B89: Account Type | C89: Location | D89: No. of Visits | E89: Total Time (mins) | F89: Avg Time (mins) | G89: Last Visit Date | H89: Top Employee
A90: =PivotData!A12 -> ABC Agencies | B90: =PivotData!B12 -> Distributor | C90: =PivotData!C12 -> Coimbatore | D90: =PivotData!D12 -> 69 | E90: =PivotData!E12 -> 4945 | F90: =PivotData!F12 -> 71.666667 | G90: =PivotData!G12 -> 46203 | H90: =PivotData!H12 -> Kiran
A91: =PivotData!A13 -> Elite Dealers | B91: =PivotData!B13 -> Distributor | C91: =PivotData!C13 -> Chennai | D91: =PivotData!D13 -> 59 | E91: =PivotData!E13 -> 4119 | F91: =PivotData!F13 -> 69.813559 | G91: =PivotData!G13 -> 46203 | H91: =PivotData!H13 -> John
A92: =PivotData!A14 -> Metro Site | B92: =PivotData!B14 -> Distributor | C92: =PivotData!C14 -> Chennai | D92: =PivotData!D14 -> 53 | E92: =PivotData!E14 -> 3291 | F92: =PivotData!F14 -> 62.09434 | G92: =PivotData!G14 -> 46203 | H92: =PivotData!H14 -> Priya
A93: =PivotData!A15 -> Prime Traders | B93: =PivotData!B15 -> Distributor | C93: =PivotData!C15 -> Chennai | D93: =PivotData!D15 -> 63 | E93: =PivotData!E15 -> 4222 | F93: =PivotData!F15 -> 67.015873 | G93: =PivotData!G15 -> 46203 | H93: =PivotData!H15 -> Priya
A94: =PivotData!A16 -> XYZ Motors | B94: =PivotData!B16 -> OEM | C94: =PivotData!C16 -> Coimbatore | D94: =PivotData!D16 -> 56 | E94: =PivotData!E16 -> 4087 | F94: =PivotData!F16 -> 72.982143 | G94: =PivotData!G16 -> 46203 | H94: =PivotData!H16 -> Priya
A96: MONTHLY SUMMARY
A97: Month | B97: Working Days | C97: Total Visits | D97: Successful | E97: Pending | F97: Total Hours | G97: Avg Hours/Day
A98: =PivotData!E22 -> 46174 | B98: =PivotData!F22 -> 30 | C98: =PivotData!G22 -> 300 | D98: =PivotData!H22 -> 300 | E98: =PivotData!I22 -> 0 | F98: =PivotData!J22 -> 344.4 | G98: =PivotData!K22 -> 11.48
A99: =PivotData!E23 -> 46204 | B99: =PivotData!F23 -> 0 | C99: =PivotData!G23 -> 0 | D99: =PivotData!H23 -> 0 | E99: =PivotData!I23 -> 0 | F99: =PivotData!J23 -> 0 | G99: =PivotData!K23 -> 0
A100: =PivotData!E24 -> 46235 | B100: =PivotData!F24 -> 0 | C100: =PivotData!G24 -> 0 | D100: =PivotData!H24 -> 0 | E100: =PivotData!I24 -> 0 | F100: =PivotData!J24 -> 0 | G100: =PivotData!K24 -> 0
A101: =PivotData!E25 -> 46266 | B101: =PivotData!F25 -> 0 | C101: =PivotData!G25 -> 0 | D101: =PivotData!H25 -> 0 | E101: =PivotData!I25 -> 0 | F101: =PivotData!J25 -> 0 | G101: =PivotData!K25 -> 0
A102: =PivotData!E26 -> 46296 | B102: =PivotData!F26 -> 0 | C102: =PivotData!G26 -> 0 | D102: =PivotData!H26 -> 0 | E102: =PivotData!I26 -> 0 | F102: =PivotData!J26 -> 0 | G102: =PivotData!K26 -> 0
A103: =PivotData!E27 -> 46327 | B103: =PivotData!F27 -> 0 | C103: =PivotData!G27 -> 0 | D103: =PivotData!H27 -> 0 | E103: =PivotData!I27 -> 0 | F103: =PivotData!J27 -> 0 | G103: =PivotData!K27 -> 0
A104: =PivotData!E28 -> 46357 | B104: =PivotData!F28 -> 0 | C104: =PivotData!G28 -> 0 | D104: =PivotData!H28 -> 0 | E104: =PivotData!I28 -> 0 | F104: =PivotData!J28 -> 0 | G104: =PivotData!K28 -> 0
A105: =PivotData!E29 -> 46388 | B105: =PivotData!F29 -> 0 | C105: =PivotData!G29 -> 0 | D105: =PivotData!H29 -> 0 | E105: =PivotData!I29 -> 0 | F105: =PivotData!J29 -> 0 | G105: =PivotData!K29 -> 0
A106: =PivotData!E30 -> 46419 | B106: =PivotData!F30 -> 0 | C106: =PivotData!G30 -> 0 | D106: =PivotData!H30 -> 0 | E106: =PivotData!I30 -> 0 | F106: =PivotData!J30 -> 0 | G106: =PivotData!K30 -> 0
A107: =PivotData!E31 -> 46447 | B107: =PivotData!F31 -> 0 | C107: =PivotData!G31 -> 0 | D107: =PivotData!H31 -> 0 | E107: =PivotData!I31 -> 0 | F107: =PivotData!J31 -> 0 | G107: =PivotData!K31 -> 0
A108: =PivotData!E32 -> 46478 | B108: =PivotData!F32 -> 0 | C108: =PivotData!G32 -> 0 | D108: =PivotData!H32 -> 0 | E108: =PivotData!I32 -> 0 | F108: =PivotData!J32 -> 0 | G108: =PivotData!K32 -> 0
A109: =PivotData!E33 -> 46508 | B109: =PivotData!F33 -> 0 | C109: =PivotData!G33 -> 0 | D109: =PivotData!H33 -> 0 | E109: =PivotData!I33 -> 0 | F109: =PivotData!J33 -> 0 | G109: =PivotData!K33 -> 0
A112: EMPLOYEE DRILL-DOWN (based on Selected Employee above)
A113: Total Visits | B113: =PivotData!B57 -> 60 | D113: Top Outlets (Selected Employee) | G113: Account Type Mix (Selected Employee)
A114: Working Days | B114: =PivotData!B58 -> 28 | D114: =PivotData!D57 -> ABC Agencies | E114: =PivotData!E57 -> 15 | G114: =PivotData!G57 -> Distributor | H114: =PivotData!H57 -> 18
A115: Total Hours | B115: =PivotData!B59 -> 72.883333 | D115: =PivotData!D58 -> Elite Dealers | E115: =PivotData!E58 -> 10 | G115: =PivotData!G58 -> OEM | H115: =PivotData!H58 -> 13
...

Sheet Raw_Data
A1: Date | B1: Employee | C1: UniqueKey | D1: Account Type | E1: Outlet Name | F1: Location | G1: Start Time | H1: End Time | I1: Time Spent (mins) | J1: Visit Type | K1: Status | L1: Month | M1: MonthKey
A2: 46174 | B2: Arun | C2: A456 | D2: Distributor | E2: ABC Agencies | F2: Coimbatore | G2: 0.375 | H2: 0.42638889 | I2: 74 | J2: Follow-up | K2: Completed | L2: =TEXT(A2,"mmm-yyyy") -> Jun-2026 | M2: =DATE(YEAR(A2),MONTH(A2),1) -> 46174
A3: 46175 | B3: Kiran | C3: A457 | D3: Distributor | E3: Prime Traders | F3: Chennai | G3: 0.375 | H3: 0.39930556 | I3: 35 | J3: Demo | K3: Completed | L3: =TEXT(A3,"mmm-yyyy") -> Jun-2026 | M3: =DATE(YEAR(A3),MONTH(A3),1) -> 46174
A4: 46176 | B4: Arun | C4: A457 | D4: OEM | E4: Prime Traders | F4: Coimbatore | G4: 0.53125 | H4: 0.59583333 | I4: 93 | J4: Collection | K4: Completed | L4: =TEXT(A4,"mmm-yyyy") -> Jun-2026 | M4: =DATE(YEAR(A4),MONTH(A4),1) -> 46174
A5: 46177 | B5: Kiran | C5: A457 | D5: Dealer | E5: Prime Traders | F5: Chennai | G5: 0.38541667 | H5: 0.41805556 | I5: 47 | J5: Follow-up | K5: Completed | L5: =TEXT(A5,"mmm-yyyy") -> Jun-2026 | M5: =DATE(YEAR(A5),MONTH(A5),1) -> 46174
A6: 46178 | B6: Kiran | C6: A456 | D6: Dealer | E6: ABC Agencies | F6: Chennai | G6: 0.46875 | H6: 0.52083333 | I6: 75 | J6: Demo | K6: Completed | L6: =TEXT(A6,"mmm-yyyy") -> Jun-2026 | M6: =DATE(YEAR(A6),MONTH(A6),1) -> 46174
A7: 46179 | B7: Priya | C7: A458 | D7: OEM | E7: XYZ Motors | F7: Coimbatore | G7: 0.5625 | H7: 0.61111111 | I7: 70 | J7: Collection | K7: Completed | L7: =TEXT(A7,"mmm-yyyy") -> Jun-2026 | M7: =DATE(YEAR(A7),MONTH(A7),1) -> 46174
A8: 46180 | B8: Kiran | C8: A459 | D8: Distributor | E8: Metro Site | F8: Chennai | G8: 0.67708333 | H8: 0.73680556 | I8: 86 | J8: Demo | K8: Completed | L8: =TEXT(A8,"mmm-yyyy") -> Jun-2026 | M8: =DATE(YEAR(A8),MONTH(A8),1) -> 46174
A9: 46181 | B9: John | C9: A458 | D9: Dealer | E9: XYZ Motors | F9: Chennai | G9: 0.48958333 | H9: 0.52986111 | I9: 58 | J9: Sales | K9: Completed | L9: =TEXT(A9,"mmm-yyyy") -> Jun-2026 | M9: =DATE(YEAR(A9),MONTH(A9),1) -> 46174
A10: 46182 | B10: Priya | C10: A459 | D10: Distributor | E10: Metro Site | F10: Salem | G10: 0.61458333 | H10: 0.66736111 | I10: 76 | J10: Sales | K10: Completed | L10: =TEXT(A10,"mmm-yyyy") -> Jun-2026 | M10: =DATE(YEAR(A10),MONTH(A10),1) -> 46174
A11: 46183 | B11: Arun | C11: A460 | D11: Distributor | E11: Elite Dealers | F11: Chennai | G11: 0.5 | H11: 0.53541667 | I11: 51 | J11: Collection | K11: Completed | L11: =TEXT(A11,"mmm-yyyy") -> Jun-2026 | M11: =DATE(YEAR(A11),MONTH(A11),1) -> 46174
A12: 46184 | B12: Arun | C12: A457 | D12: Dealer | E12: Prime Traders | F12: Chennai | G12: 0.65625 | H12: 0.7 | I12: 63 | J12: Sales | K12: Completed | L12: =TEXT(A12,"mmm-yyyy") -> Jun-2026 | M12: =DATE(YEAR(A12),MONTH(A12),1) -> 46174
A13: 46185 | B13: David | C13: A458 | D13: Distributor | E13: XYZ Motors | F13: Salem | G13: 0.41666667 | H13: 0.45486111 | I13: 55 | J13: Sales | K13: Completed | L13: =TEXT(A13,"mmm-yyyy") -> Jun-2026 | M13: =DATE(YEAR(A13),MONTH(A13),1) -> 46174
... A301: 46203 | B301: Priya | C301: A460 | D301: OEM | E301: Elite Dealers | F301: Coimbatore | G301: 0.53125 | H301: 0.55416667 | I301: 33 | J301: Follow-up | K301: Completed | L301: =TEXT(A301,"mmm-yyyy") -> Jun-2026 | M301: =DATE(YEAR(A301),MONTH(A301),1) -> 46174

Sheet Calculations
A1: Employee Master (distinct names) | C1: Account Type Master | E1: Status Master | G1: Location Master | I1: Visit Type Master
A2: Employee | C2: Account Type | E2: Status | G2: Location | I2: Visit Type
A3: Arun | C3: Distributor | E3: Completed | G3: Coimbatore | I3: Follow-up
A4: Kiran | C4: OEM | E4: Pending | G4: Chennai | I4: Demo
A5: Priya | C5: Dealer | E5: Cancelled | G5: Salem | I5: Collection
A6: John | C6: Project Site | I6: Sales
A7: David
A10: Outlet Master (distinct names)
A11: Outlet Name
A12: ABC Agencies
A13: Elite Dealers
A14: Metro Site
A15: Prime Traders
A16: XYZ Motors

Sheet PivotData
A1: Visits & Time by Employee | K1: Visits & Time by Account Type | P1: Visits by Status | S1: Visits by Location | V1: Visit Type Distribution
A2: Employee | B2: Total Visits | C2: Working Days | D2: Avg Visits/Day | E2: Total Time (mins) | F2: Total Time (hrs) | G2: Avg Time/Visit | H2: Success Rate | I2: Rank | K2: Account Type | L2: Visits | M2: Time Spent (mins) | N2: Time Spent (hrs) | P2: Status | Q2: Visits | S2: Location | T2: Visits | V2: Visit Type | W2: Visits
A3: =Calculations!A3 -> Arun | B3: =COUNTIF(RawDataTable[Employee],A3) -> 60 | C3: =SUMPRODUCT((RawDataTable[Employee]=A3)/COUNTIFS(RawDataTable[Employee],RawDataTable[Employee],RawDataTable[Date],RawDataTable[Date])) -> 28 | D3: =IFERROR(B3/C3,0) -> 2.1428571 | E3: =SUMIF(RawDataTable[Employee],A3,RawDataTable[Time Spent (mins)]) -> 4373 | F3: =E3/60 -> 72.883333 | G3: =IFERROR(E3/B3,0) -> 72.883333 | H3: =IFERROR(COUNTIFS(RawDataTable[Employee],A3,RawDataTable[Status],"Completed")/B3,0) -> 1 | I3: =RANK(B3,$B$3:$B$7) -> 3 | K3: =Calculations!C3 -> Distributor | L3: =COUNTIF(RawDataTable[Account Type],K3) -> 81 | M3: =SUMIF(RawDataTable[Account Type],K3,RawDataTable[Time Spent (mins)]) -> 5791 | N3: =M3/60 -> 96.516667 | P3: =Calculations!E3 -> Completed | Q3: =COUNTIF(RawDataTable[Status],P3) -> 300 | S3: =Calculations!G3 -> Coimbatore | T3: =COUNTIF(RawDataTable[Location],S3) -> 95 | V3: =Calculations!I3 -> Follow-up | W3: =COUNTIF(RawDataTable[Visit Type],V3) -> 77
A4: =Calculations!A4 -> Kiran | B4: =COUNTIF(RawDataTable[Employee],A4) -> 66 | C4: =SUMPRODUCT((RawDataTable[Employee]=A4)/COUNTIFS(RawDataTable[Employee],RawDataTable[Employee],RawDataTable[Date],RawDataTable[Date])) -> 28 | D4: =IFERROR(B4/C4,0) -> 2.3571429 | E4: =SUMIF(RawDataTable[Employee],A4,RawDataTable[Time Spent (mins)]) -> 4768 | F4: =E4/60 -> 79.466667 | G4: =IFERROR(E4/B4,0) -> 72.242424 | H4: =IFERROR(COUNTIFS(RawDataTable[Employee],A4,RawDataTable[Status],"Completed")/B4,0) -> 1 | I4: =RANK(B4,$B$3:$B$7) -> 1 | K4: =Calculations!C4 -> OEM | L4: =COUNTIF(RawDataTable[Account Type],K4) -> 75 | M4: =SUMIF(RawDataTable[Account Type],K4,RawDataTable[Time Spent (mins)]) -> 5116 | N4: =M4/60 -> 85.266667 | P4: =Calculations!E4 -> Pending | Q4: =COUNTIF(RawDataTable[Status],P4) -> 0 | S4: =Calculations!G4 -> Chennai | T4: =COUNTIF(RawDataTable[Location],S4) -> 99 | V4: =Calculations!I4 -> Demo | W4: =COUNTIF(RawDataTable[Visit Type],V4) -> 68
A5: =Calculations!A5 -> Priya | B5: =COUNTIF(RawDataTable[Employee],A5) -> 59 | C5: =SUMPRODUCT((RawDataTable[Employee]=A5)/COUNTIFS(RawDataTable[Employee],RawDataTable[Employee],RawDataTable[Date],RawDataTable[Date])) -> 29 | D5: =IFERROR(B5/C5,0) -> 2.0344828 | E5: =SUMIF(RawDataTable[Employee],A5,RawDataTable[Time Spent (mins)]) -> 3489 | F5: =E5/60 -> 58.15 | G5: =IFERROR(E5/B5,0) -> 59.135593 | H5: =IFERROR(COUNTIFS(RawDataTable[Employee],A5,RawDataTable[Status],"Completed")/B5,0) -> 1 | I5: =RANK(B5,$B$3:$B$7) -> 4 | K5: =Calculations!C5 -> Dealer | L5: =COUNTIF(RawDataTable[Account Type],K5) -> 77 | M5: =SUMIF(RawDataTable[Account Type],K5,RawDataTable[Time Spent (mins)]) -> 5105 | N5: =M5/60 -> 85.083333 | P5: =Calculations!E5 -> Cancelled | Q5: =COUNTIF(RawDataTable[Status],P5) -> 0 | S5: =Calculations!G5 -> Salem | T5: =COUNTIF(RawDataTable[Location],S5) -> 106 | V5: =Calculations!I5 -> Collection | W5: =COUNTIF(RawDataTable[Visit Type],V5) -> 75
A6: =Calculations!A6 -> John | B6: =COUNTIF(RawDataTable[Employee],A6) -> 61 | C6: =SUMPRODUCT((RawDataTable[Employee]=A6)/COUNTIFS(RawDataTable[Employee],RawDataTable[Employee],RawDataTable[Date],RawDataTable[Date])) -> 28 | D6: =IFERROR(B6/C6,0) -> 2.1785714 | E6: =SUMIF(RawDataTable[Employee],A6,RawDataTable[Time Spent (mins)]) -> 4383 | F6: =E6/60 -> 73.05 | G6: =IFERROR(E6/B6,0) -> 71.852459 | H6: =IFERROR(COUNTIFS(RawDataTable[Employee],A6,RawDataTable[Status],"Completed")/B6,0) -> 1 | I6: =RANK(B6,$B$3:$B$7) -> 2 | K6: =Calculations!C6 -> Project Site | L6: =COUNTIF(RawDataTable[Account Type],K6) -> 67 | M6: =SUMIF(RawDataTable[Account Type],K6,RawDataTable[Time Spent (mins)]) -> 4652 | N6: =M6/60 -> 77.533333 | V6: =Calculations!I6 -> Sales | W6: =COUNTIF(RawDataTable[Visit Type],V6) -> 80
A7: =Calculations!A7 -> David | B7: =COUNTIF(RawDataTable[Employee],A7) -> 54 | C7: =SUMPRODUCT((RawDataTable[Employee]=A7)/COUNTIFS(RawDataTable[Employee],RawDataTable[Employee],RawDataTable[Date],RawDataTable[Date])) -> 26 | D7: =IFERROR(B7/C7,0) -> 2.0769231 | E7: =SUMIF(RawDataTable[Employee],A7,RawDataTable[Time Spent (mins)]) -> 3651 | F7: =E7/60 -> 60.85 | G7: =IFERROR(E7/B7,0) -> 67.611111 | H7: =IFERROR(COUNTIFS(RawDataTable[Employee],A7,RawDataTable[Status],"Completed")/B7,0) -> 1 | I7: =RANK(B7,$B$3:$B$7) -> 5
A10: Outlet Analysis | J10: Top Outlets by Visits
A11: Outlet Name | B11: Account Type | C11: Location | D11: No. of Visits | E11: Total Time (mins) | F11: Avg Time (mins) | G11: Last Visit Date | H11: Top Employee | J11: Outlet Name | K11: Visits
A12: =Calculations!A12 -> ABC Agencies | B12: =INDEX(RawDataTable[Account Type],MATCH(A12,RawDataTable[Outlet Name],0)) -> Distributor | C12: =INDEX(RawDataTable[Location],MATCH(A12,RawDataTable[Outlet Name],0)) -> Coimbatore | D12: =COUNTIF(RawDataTable[Outlet Name],A12) -> 69 | E12: =SUMIF(RawDataTable[Outlet Name],A12,RawDataTable[Time Spent (mins)]) -> 4945 | F12: =IFERROR(E12/D12,0) -> 71.666667 | G12: {=MAX(IF(RawDataTable[Outlet Name]=A12,RawDataTable[Date]))} -> 46203 | H12: {=INDEX($A$3:$A$7,MATCH(MAX(COUNTIFS(RawDataTable[Employee],$A$3:$A$7,RawDataTable[Outlet Name],A12)),COUNTIFS(RawDataTable[Employee],$A$3:$A$7,RawDataTable[Outlet Name],A12),0))} -> Kiran | J12: {=INDEX($A$12:$A$16,MATCH(LARGE($D$12:$D$16+ROW($D$12:$D$16)/10000,1),$D$12:$D$16+ROW($D$12:$D$16)/10000,0))} -> ABC Agencies | K12: =VLOOKUP(J12,$A$12:$D$16,4,FALSE()) -> 69
A13: =Calculations!A13 -> Elite Dealers | B13: =INDEX(RawDataTable[Account Type],MATCH(A13,RawDataTable[Outlet Name],0)) -> Distributor | C13: =INDEX(RawDataTable[Location],MATCH(A13,RawDataTable[Outlet Name],0)) -> Chennai | D13: =COUNTIF(RawDataTable[Outlet Name],A13) -> 59 | E13: =SUMIF(RawDataTable[Outlet Name],A13,RawDataTable[Time Spent (mins)]) -> 4119 | F13: =IFERROR(E13/D13,0) -> 69.813559 | G13: {=MAX(IF(RawDataTable[Outlet Name]=A13,RawDataTable[Date]))} -> 46203 | H13: {=INDEX($A$3:$A$7,MATCH(MAX(COUNTIFS(RawDataTable[Employee],$A$3:$A$7,RawDataTable[Outlet Name],A13)),COUNTIFS(RawDataTable[Employee],$A$3:$A$7,RawDataTable[Outlet Name],A13),0))} -> John | J13: {=INDEX($A$12:$A$16,MATCH(LARGE($D$12:$D$16+ROW($D$12:$D$16)/10000,2),$D$12:$D$16+ROW($D$12:$D$16)/10000,0))} -> Prime Traders | K13: =VLOOKUP(J13,$A$12:$D$16,4,FALSE()) -> 63
A14: =Calculations!A14 -> Metro Site | B14: =INDEX(RawDataTable[Account Type],MATCH(A14,RawDataTable[Outlet Name],0)) -> Distributor | C14: =INDEX(RawDataTable[Location],MATCH(A14,RawDataTable[Outlet Name],0)) -> Chennai | D14: =COUNTIF(RawDataTable[Outlet Name],A14) -> 53 | E14: =SUMIF(RawDataTable[Outlet Name],A14,RawDataTable[Time Spent (mins)]) -> 3291 | F14: =IFERROR(E14/D14,0) -> 62.09434 | G14: {=MAX(IF(RawDataTable[Outlet Name]=A14,RawDataTable[Date]))} -> 46203 | H14: {=INDEX($A$3:$A$7,MATCH(MAX(COUNTIFS(RawDataTable[Employee],$A$3:$A$7,RawDataTable[Outlet Name],A14)),COUNTIFS(RawDataTable[Employee],$A$3:$A$7,RawDataTable[Outlet Name],A14),0))} -> Priya | J14: {=INDEX($A$12:$A$16,MATCH(LARGE($D$12:$D$16+ROW($D$12:$D$16)/10000,3),$D$12:$D$16+ROW($D$12:$D$16)/10000,0))} -> Elite Dealers | K14: =VLOOKUP(J14,$A$12:$D$16,4,FALSE()) -> 59
A15: =Calculations!A15 -> Prime Traders | B15: =INDEX(RawDataTable[Account Type],MATCH(A15,RawDataTable[Outlet Name],0)) -> Distributor | C15: =INDEX(RawDataTable[Location],MATCH(A15,RawDataTable[Outlet Name],0)) -> Chennai | D15: =COUNTIF(RawDataTable[Outlet Name],A15) -> 63 | E15: =SUMIF(RawDataTable[Outlet Name],A15,RawDataTable[Time Spent (mins)]) -> 4222 | F15: =IFERROR(E15/D15,0) -> 67.015873 | G15: {=MAX(IF(RawDataTable[Outlet Name]=A15,RawDataTable[Date]))} -> 46203 | H15: {=INDEX($A$3:$A$7,MATCH(MAX(COUNTIFS(RawDataTable[Employee],$A$3:$A$7,RawDataTable[Outlet Name],A15)),COUNTIFS(RawDataTable[Employee],$A$3:$A$7,RawDataTable[Outlet Name],A15),0))} -> Priya | J15: {=INDEX($A$12:$A$16,MATCH(LARGE($D$12:$D$16+ROW($D$12:$D$16)/10000,4),$D$12:$D$16+ROW($D$12:$D$16)/10000,0))} -> XYZ Motors | K15: =VLOOKUP(J15,$A$12:$D$16,4,FALSE()) -> 56
A16: =Calculations!A16 -> XYZ Motors | B16: =INDEX(RawDataTable[Account Type],MATCH(A16,RawDataTable[Outlet Name],0)) -> OEM | C16: =INDEX(RawDataTable[Location],MATCH(A16,RawDataTable[Outlet Name],0)) -> Coimbatore | D16: =COUNTIF(RawDataTable[Outlet Name],A16) -> 56 | E16: =SUMIF(RawDataTable[Outlet Name],A16,RawDataTable[Time Spent (mins)]) -> 4087 | F16: =IFERROR(E16/D16,0) -> 72.982143 | G16: {=MAX(IF(RawDataTable[Outlet Name]=A16,RawDataTable[Date]))} -> 46203 | H16: {=INDEX($A$3:$A$7,MATCH(MAX(COUNTIFS(RawDataTable[Employee],$A$3:$A$7,RawDataTable[Outlet Name],A16)),COUNTIFS(RawDataTable[Employee],$A$3:$A$7,RawDataTable[Outlet Name],A16),0))} -> Priya | J16: {=INDEX($A$12:$A$16,MATCH(LARGE($D$12:$D$16+ROW($D$12:$D$16)/10000,5),$D$12:$D$16+ROW($D$12:$D$16)/10000,0))} -> Metro Site | K16: =VLOOKUP(J16,$A$12:$D$16,4,FALSE()) -> 53
A20: Daily Visit Trend | E20: Monthly Summary
A21: Date | B21: Visits | C21: Hours | E21: Month | F21: Working Days | G21: Total Visits | H21: Successful | I21: Pending | J21: Total Hours | K21: Avg Hours/Day
A22: =IF(MIN(RawDataTable[Date])+0<=MAX(RawDataTable[Date]),MIN(RawDataTable[Date])+0,"") -> 46174 | B22: =IF(A22="","",COUNTIF(RawDataTable[Date],A22)) -> 10 | C22: =IF(A22="","",SUMIF(RawDataTable[Date],A22,RawDataTable[Time Spent (mins)])/60) -> 13.15 | E22: =EDATE(DATE(YEAR(MIN(RawDataTable[Date])),MONTH(MIN(RawDataTable[Date])),1),0) -> 46174 | F22: =IF(SUMPRODUCT((RawDataTable[MonthKey]=E22)*1)=0,0,SUMPRODUCT(((RawDataTable[MonthKey]=E22))/COUNTIFS(RawDataTable[Date],RawDataTable[Date],RawDataTable[MonthKey],RawDataTable[MonthKey]))) -> 30 | G22: =COUNTIFS(RawDataTable[MonthKey],E22) -> 300 | H22: =COUNTIFS(RawDataTable[MonthKey],E22,RawDataTable[Status],"Completed") -> 300 | I22: =COUNTIFS(RawDataTable[MonthKey],E22,RawDataTable[Status],"Pending") -> 0 | J22: =SUMIFS(RawDataTable[Time Spent (mins)],RawDataTable[MonthKey],E22)/60 -> 344.4 | K22: =IFERROR(J22/F22,0) -> 11.48
A23: =IF(MIN(RawDataTable[Date])+1<=MAX(RawDataTable[Date]),MIN(RawDataTable[Date])+1,"") -> 46175 | B23: =IF(A23="","",COUNTIF(RawDataTable[Date],A23)) -> 10 | C23: =IF(A23="","",SUMIF(RawDataTable[Date],A23,RawDataTable[Time Spent (mins)])/60) -> 9.3833333 | E23: =EDATE(DATE(YEAR(MIN(RawDataTable[Date])),MONTH(MIN(RawDataTable[Date])),1),1) -> 46204 | F23: =IF(SUMPRODUCT((RawDataTable[MonthKey]=E23)*1)=0,0,SUMPRODUCT(((RawDataTable[MonthKey]=E23))/COUNTIFS(RawDataTable[Date],RawDataTable[Date],RawDataTable[MonthKey],RawDataTable[MonthKey]))) -> 0 | G23: =COUNTIFS(RawDataTable[MonthKey],E23) -> 0 | H23: =COUNTIFS(RawDataTable[MonthKey],E23,RawDataTable[Status],"Completed") -> 0 | I23: =COUNTIFS(RawDataTable[MonthKey],E23,RawDataTable[Status],"Pending") -> 0 | J23: =SUMIFS(RawDataTable[Time Spent (mins)],RawDataTable[MonthKey],E23)/60 -> 0 | K23: =IFERROR(J23/F23,0) -> 0
A24: =IF(MIN(RawDataTable[Date])+2<=MAX(RawDataTable[Date]),MIN(RawDataTable[Date])+2,"") -> 46176 | B24: =IF(A24="","",COUNTIF(RawDataTable[Date],A24)) -> 10 | C24: =IF(A24="","",SUMIF(RawDataTable[Date],A24,RawDataTable[Time Spent (mins)])/60) -> 12.516667 | E24: =EDATE(DATE(YEAR(MIN(RawDataTable[Date])),MONTH(MIN(RawDataTable[Date])),1),2) -> 46235 | F24: =IF(SUMPRODUCT((RawDataTable[MonthKey]=E24)*1)=0,0,SUMPRODUCT(((RawDataTable[MonthKey]=E24))/COUNTIFS(RawDataTable[Date],RawDataTable[Date],RawDataTable[MonthKey],RawDataTable[MonthKey]))) -> 0 | G24: =COUNTIFS(RawDataTable[MonthKey],E24) -> 0 | H24: =COUNTIFS(RawDataTable[MonthKey],E24,RawDataTable[Status],"Completed") -> 0 | I24: =COUNTIFS(RawDataTable[MonthKey],E24,RawDataTable[Status],"Pending") -> 0 | J24: =SUMIFS(RawDataTable[Time Spent (mins)],RawDataTable[MonthKey],E24)/60 -> 0 | K24: =IFERROR(J24/F24,0) -> 0
A25: =IF(MIN(RawDataTable[Date])+3<=MAX(RawDataTable[Date]),MIN(RawDataTable[Date])+3,"") -> 46177 | B25: =IF(A25="","",COUNTIF(RawDataTable[Date],A25)) -> 10 | C25: =IF(A25="","",SUMIF(RawDataTable[Date],A25,RawDataTable[Time Spent (mins)])/60) -> 11.75 | E25: =EDATE(DATE(YEAR(MIN(RawDataTable[Date])),MONTH(MIN(RawDataTable[Date])),1),3) -> 46266 | F25: =IF(SUMPRODUCT((RawDataTable[MonthKey]=E25)*1)=0,0,SUMPRODUCT(((RawDataTable[MonthKey]=E25))/COUNTIFS(RawDataTable[Date],RawDataTable[Date],RawDataTable[MonthKey],RawDataTable[MonthKey]))) -> 0 | G25: =COUNTIFS(RawDataTable[MonthKey],E25) -> 0 | H25: =COUNTIFS(RawDataTable[MonthKey],E25,RawDataTable[Status],"Completed") -> 0 | I25: =COUNTIFS(RawDataTable[MonthKey],E25,RawDataTable[Status],"Pending") -> 0 | J25: =SUMIFS(RawDataTable[Time Spent (mins)],RawDataTable[MonthKey],E25)/60 -> 0 | K25: =IFERROR(J25/F25,0) -> 0
A26: =IF(MIN(RawDataTable[Date])+4<=MAX(RawDataTable[Date]),MIN(RawDataTable[Date])+4,"") -> 46178 | B26: =IF(A26="","",COUNTIF(RawDataTable[Date],A26)) -> 10 | C26: =IF(A26="","",SUMIF(RawDataTable[Date],A26,RawDataTable[Time Spent (mins)])/60) -> 11.516667 | E26: =EDATE(DATE(YEAR(MIN(RawDataTable[Date])),MONTH(MIN(RawDataTable[Date])),1),4) -> 46296 | F26: =IF(SUMPRODUCT((RawDataTable[MonthKey]=E26)*1)=0,0,SUMPRODUCT(((RawDataTable[MonthKey]=E26))/COUNTIFS(RawDataTable[Date],RawDataTable[Date],RawDataTable[MonthKey],RawDataTable[MonthKey]))) -> 0 | G26: =COUNTIFS(RawDataTable[MonthKey],E26) -> 0 | H26: =COUNTIFS(RawDataTable[MonthKey],E26,RawDataTable[Status],"Completed") -> 0 | I26: =COUNTIFS(RawDataTable[MonthKey],E26,RawDataTable[Status],"Pending") -> 0 | J26: =SUMIFS(RawDataTable[Time Spent (mins)],RawDataTable[MonthKey],E26)/60 -> 0 | K26: =IFERROR(J26/F26,0) -> 0
A27: =IF(MIN(RawDataTable[Date])+5<=MAX(RawDataTable[Date]),MIN(RawDataTable[Date])+5,"") -> 46179 | B27: =IF(A27="","",COUNTIF(RawDataTable[Date],A27)) -> 10 | C27: =IF(A27="","",SUMIF(RawDataTable[Date],A27,RawDataTable[Time Spent (mins)])/60) -> 12 | E27: =EDATE(DATE(YEAR(MIN(RawDataTable[Date])),MONTH(MIN(RawDataTable[Date])),1),5) -> 46327 | F27: =IF(SUMPRODUCT((RawDataTable[MonthKey]=E27)*1)=0,0,SUMPRODUCT(((RawDataTable[MonthKey]=E27))/COUNTIFS(RawDataTable[Date],RawDataTable[Date],RawDataTable[MonthKey],RawDataTable[MonthKey]))) -> 0 | G27: =COUNTIFS(RawDataTable[MonthKey],E27) -> 0 | H27: =COUNTIFS(RawDataTable[MonthKey],E27,RawDataTable[Status],"Completed") -> 0 | I27: =COUNTIFS(RawDataTable[MonthKey],E27,RawDataTable[Status],"Pending") -> 0 | J27: =SUMIFS(RawDataTable[Time Spent (mins)],RawDataTable[MonthKey],E27)/60 -> 0 | K27: =IFERROR(J27/F27,0) -> 0
A28: =IF(MIN(RawDataTable[Date])+6<=MAX(RawDataTable[Date]),MIN(RawDataTable[Date])+6,"") -> 46180 | B28: =IF(A28="","",COUNTIF(RawDataTable[Date],A28)) -> 10 | C28: =IF(A28="","",SUMIF(RawDataTable[Date],A28,RawDataTable[Time Spent (mins)])/60) -> 12.9 | E28: =EDATE(DATE(YEAR(MIN(RawDataTable[Date])),MONTH(MIN(RawDataTable[Date])),1),6) -> 46357 | F28: =IF(SUMPRODUCT((RawDataTable[MonthKey]=E28)*1)=0,0,SUMPRODUCT(((RawDataTable[MonthKey]=E28))/COUNTIFS(RawDataTable[Date],RawDataTable[Date],RawDataTable[MonthKey],RawDataTable[MonthKey]))) -> 0 | G28: =COUNTIFS(RawDataTable[MonthKey],E28) -> 0 | H28: =COUNTIFS(RawDataTable[MonthKey],E28,RawDataTable[Status],"Completed") -> 0 | I28: =COUNTIFS(RawDataTable[MonthKey],E28,RawDataTable[Status],"Pending") -> 0 | J28: =SUMIFS(RawDataTable[Time Spent (mins)],RawDataTable[MonthKey],E28)/60 -> 0 | K28: =IFERROR(J28/F28,0) -> 0
A29: =IF(MIN(RawDataTable[Date])+7<=MAX(RawDataTable[Date]),MIN(RawDataTable[Date])+7,"") -> 46181 | B29: =IF(A29="","",COUNTIF(RawDataTable[Date],A29)) -> 10 | C29: =IF(A29="","",SUMIF(RawDataTable[Date],A29,RawDataTable[Time Spent (mins)])/60) -> 11.25 | E29: =EDATE(DATE(YEAR(MIN(RawDataTable[Date])),MONTH(MIN(RawDataTable[Date])),1),7) -> 46388 | F29: =IF(SUMPRODUCT((RawDataTable[MonthKey]=E29)*1)=0,0,SUMPRODUCT(((RawDataTable[MonthKey]=E29))/COUNTIFS(RawDataTable[Date],RawDataTable[Date],RawDataTable[MonthKey],RawDataTable[MonthKey]))) -> 0 | G29: =COUNTIFS(RawDataTable[MonthKey],E29) -> 0 | H29: =COUNTIFS(RawDataTable[MonthKey],E29,RawDataTable[Status],"Completed") -> 0 | I29: =COUNTIFS(RawDataTable[MonthKey],E29,RawDataTable[Status],"Pending") -> 0 | J29: =SUMIFS(RawDataTable[Time Spent (mins)],RawDataTable[MonthKey],E29)/60 -> 0 | K29: =IFERROR(J29/F29,0) -> 0
A30: =IF(MIN(RawDataTable[Date])+8<=MAX(RawDataTable[Date]),MIN(RawDataTable[Date])+8,"") -> 46182 | B30: =IF(A30="","",COUNTIF(RawDataTable[Date],A30)) -> 10 | C30: =IF(A30="","",SUMIF(RawDataTable[Date],A30,RawDataTable[Time Spent (mins)])/60) -> 12.566667 | E30: =EDATE(DATE(YEAR(MIN(RawDataTable[Date])),MONTH(MIN(RawDataTable[Date])),1),8) -> 46419 | F30: =IF(SUMPRODUCT((RawDataTable[MonthKey]=E30)*1)=0,0,SUMPRODUCT(((RawDataTable[MonthKey]=E30))/COUNTIFS(RawDataTable[Date],RawDataTable[Date],RawDataTable[MonthKey],RawDataTable[MonthKey]))) -> 0 | G30: =COUNTIFS(RawDataTable[MonthKey],E30) -> 0 | H30: =COUNTIFS(RawDataTable[MonthKey],E30,RawDataTable[Status],"Completed") -> 0 | I30: =COUNTIFS(RawDataTable[MonthKey],E30,RawDataTable[Status],"Pending") -> 0 | J30: =SUMIFS(RawDataTable[Time Spent (mins)],RawDataTable[MonthKey],E30)/60 -> 0 | K30: =IFERROR(J30/F30,0) -> 0
A31: =IF(MIN(RawDataTable[Date])+9<=MAX(RawDataTable[Date]),MIN(RawDataTable[Date])+9,"") -> 46183 | B31: =IF(A31="","",COUNTIF(RawDataTable[Date],A31)) -> 10 | C31: =IF(A31="","",SUMIF(RawDataTable[Date],A31,RawDataTable[Time Spent (mins)])/60) -> 11.816667 | E31: =EDATE(DATE(YEAR(MIN(RawDataTable[Date])),MONTH(MIN(RawDataTable[Date])),1),9) -> 46447 | F31: =IF(SUMPRODUCT((RawDataTable[MonthKey]=E31)*1)=0,0,SUMPRODUCT(((RawDataTable[MonthKey]=E31))/COUNTIFS(RawDataTable[Date],RawDataTable[Date],RawDataTable[MonthKey],RawDataTable[MonthKey]))) -> 0 | G31: =COUNTIFS(RawDataTable[MonthKey],E31) -> 0 | H31: =COUNTIFS(RawDataTable[MonthKey],E31,RawDataTable[Status],"Completed") -> 0 | I31: =COUNTIFS(RawDataTable[MonthKey],E31,RawDataTable[Status],"Pending") -> 0 | J31: =SUMIFS(RawDataTable[Time Spent (mins)],RawDataTable[MonthKey],E31)/60 -> 0 | K31: =IFERROR(J31/F31,0) -> 0
A32: =IF(MIN(RawDataTable[Date])+10<=MAX(RawDataTable[Date]),MIN(RawDataTable[Date])+10,"") -> 46184 | B32: =IF(A32="","",COUNTIF(RawDataTable[Date],A32)) -> 10 | C32: =IF(A32="","",SUMIF(RawDataTable[Date],A32,RawDataTable[Time Spent (mins)])/60) -> 10.133333 | E32: =EDATE(DATE(YEAR(MIN(RawDataTable[Date])),MONTH(MIN(RawDataTable[Date])),1),10) -> 46478 | F32: =IF(SUMPRODUCT((RawDataTable[MonthKey]=E32)*1)=0,0,SUMPRODUCT(((RawDataTable[MonthKey]=E32))/COUNTIFS(RawDataTable[Date],RawDataTable[Date],RawDataTable[MonthKey],RawDataTable[MonthKey]))) -> 0 | G32: =COUNTIFS(RawDataTable[MonthKey],E32) -> 0 | H32: =COUNTIFS(RawDataTable[MonthKey],E32,RawDataTable[Status],"Completed") -> 0 | I32: =COUNTIFS(RawDataTable[MonthKey],E32,RawDataTable[Status],"Pending") -> 0 | J32: =SUMIFS(RawDataTable[Time Spent (mins)],RawDataTable[MonthKey],E32)/60 -> 0 | K32: =IFERROR(J32/F32,0) -> 0
A33: =IF(MIN(RawDataTable[Date])+11<=MAX(RawDataTable[Date]),MIN(RawDataTable[Date])+11,"") -> 46185 | B33: =IF(A33="","",COUNTIF(RawDataTable[Date],A33)) -> 10 | C33: =IF(A33="","",SUMIF(RawDataTable[Date],A33,RawDataTable[Time Spent (mins)])/60) -> 11.9 | E33: =EDATE(DATE(YEAR(MIN(RawDataTable[Date])),MONTH(MIN(RawDataTable[Date])),1),11) -> 46508 | F33: =IF(SUMPRODUCT((RawDataTable[MonthKey]=E33)*1)=0,0,SUMPRODUCT(((RawDataTable[MonthKey]=E33))/COUNTIFS(RawDataTable[Date],RawDataTable[Date],RawDataTable[MonthKey],RawDataTable[MonthKey]))) -> 0 | G33: =COUNTIFS(RawDataTable[MonthKey],E33) -> 0 | H33: =COUNTIFS(RawDataTable[MonthKey],E33,RawDataTable[Status],"Completed") -> 0 | I33: =COUNTIFS(RawDataTable[MonthKey],E33,RawDataTable[Status],"Pending") -> 0 | J33: =SUMIFS(RawDataTable[Time Spent (mins)],RawDataTable[MonthKey],E33)/60 -> 0 | K33: =IFERROR(J33/F33,0) -> 0
A34: =IF(MIN(RawDataTable[Date])+12<=MAX(RawDataTable[Date]),MIN(RawDataTable[Date])+12,"") -> 46186 | B34: =IF(A34="","",COUNTIF(RawDataTable[Date],A34)) -> 10 | C34: =IF(A34="","",SUMIF(RawDataTable[Date],A34,RawDataTable[Time Spent (mins)])/60) -> 8.2166667
A35: =IF(MIN(RawDataTable[Date])+13<=MAX(RawDataTable[Date]),MIN(RawDataTable[Date])+13,"") -> 46187 | B35: =IF(A35="","",COUNTIF(RawDataTable[Date],A35)) -> 10 | C35: =IF(A35="","",SUMIF(RawDataTable[Date],A35,RawDataTable[Time Spent (mins)])/60) -> 12.3
A36: =IF(MIN(RawDataTable[Date])+14<=MAX(RawDataTable[Date]),MIN(RawDataTable[Date])+14,"") -> 46188 | B36: =IF(A36="","",COUNTIF(RawDataTable[Date],A36)) -> 10 | C36: =IF(A36="","",SUMIF(RawDataTable[Date],A36,RawDataTable[Time Spent (mins)])/60) -> 12.65
A37: =IF(MIN(RawDataTable[Date])+15<=MAX(RawDataTable[Date]),MIN(RawDataTable[Date])+15,"") -> 46189 | B37: =IF(A37="","",COUNTIF(RawDataTable[Date],A37)) -> 10 | C37: =IF(A37="","",SUMIF(RawDataTable[Date],A37,RawDataTable[Time Spent (mins)])/60) -> 10.633333
A38: =IF(MIN(RawDataTable[Date])+16<=MAX(RawDataTable[Date]),MIN(RawDataTable[Date])+16,"") -> 46190 | B38: =IF(A38="","",COUNTIF(RawDataTable[Date],A38)) -> 10 | C38: =IF(A38="","",SUMIF(RawDataTable[Date],A38,RawDataTable[Time Spent (mins)])/60) -> 12.033333
A39: =IF(MIN(RawDataTable[Date])+17<=MAX(RawDataTable[Date]),MIN(RawDataTable[Date])+17,"") -> 46191 | B39: =IF(A39="","",COUNTIF(RawDataTable[Date],A39)) -> 10 | C39: =IF(A39="","",SUMIF(RawDataTable[Date],A39,RawDataTable[Time Spent (mins)])/60) -> 9.7333333
A40: Global KPI Values | B40: =IF(A40="","",COUNTIF(RawDataTable[Date],A40)) -> 0 | C40: =IF(A40="","",SUMIF(RawDataTable[Date],A40,RawDataTable[Time Spent (mins)])/60) -> 0
A41: Total Visits | B41: =COUNTA(RawDataTable[UniqueKey]) -> 300 | C41: =IF(A41="","",SUMIF(RawDataTable[Date],A41,RawDataTable[Time Spent (mins)])/60) -> 0
A42: Successful Visits | B42: =COUNTIF(RawDataTable[Status],"Completed") -> 300 | C42: =IF(A42="","",SUMIF(RawDataTable[Date],A42,RawDataTable[Time Spent (mins)])/60) -> 0
A43: Pending Visits | B43: =COUNTIF(RawDataTable[Status],"Pending") -> 0 | C43: =IF(A43="","",SUMIF(RawDataTable[Date],A43,RawDataTable[Time Spent (mins)])/60) -> 0
A44: Cancelled Visits | B44: =COUNTIFS(RawDataTable[Status],"Cancelled")+COUNTIFS(RawDataTable[Status],"Failed") -> 0 | C44: =IF(A44="","",SUMIF(RawDataTable[Date],A44,RawDataTable[Time Spent (mins)])/60) -> 0
A45: Total Employees | B45: =COUNTA(Calculations!$A$3:$A$7) -> 5 | C45: =IF(A45="","",SUMIF(RawDataTable[Date],A45,RawDataTable[Time Spent (mins)])/60) -> 0
...
